============================= test session starts ==============================
platform linux -- Python 3.8.10, pytest-8.1.1, pluggy-1.5.0 -- /usr/bin/python3
cachedir: .pytest_cache
hypothesis profile 'default' -> database=DirectoryBasedExampleDatabase(PosixPath('/home/rosh/projects/report-plugin/pytest_report_plugin/.hypothesis/examples'))
rootdir: /home/rosh/projects/report-plugin/pytest_report_plugin
plugins: hypothesis-6.100.1, anyio-4.3.0, Faker-24.11.0
collecting ... collected 9 items

tests/test_all_outcomes.py::test_passing {}
PASSED
tests/test_all_outcomes.py::test_error {}
PASSED
tests/test_all_outcomes.py::test_skipped {}
SKIPPED (Test is skipped fo...)
tests/test_all_outcomes.py::test_expected_failure {}
XFAIL (Expected fa...)
tests/test_all_outcomes.py::test_unexpected_failure {}
FAILED
tests/test_plugin.py::test_examples[2-2] {'left': 2, 'right': 2}
PASSED
tests/test_plugin.py::test_examples[3.14-5.55] {'left': 3.14, 'right': 5.55}
SKIPPED (Skipped!)
tests/test_plugin.py::test_examples[nan-42] {'left': nan, 'right': 42}
FAILED
tests/test_plugin.py::test_properties {}
FAILED

=================================== FAILURES ===================================
___________________________ test_unexpected_failure ____________________________

    def test_unexpected_failure():
>       assert False
E       assert False

tests/test_all_outcomes.py:20: AssertionError
------------------------------ Captured log setup ------------------------------
INFO     pytest_report_plugin.plugin:plugin.py:263 Started test: test_unexpected_failure
INFO     pytest_report_plugin.plugin:plugin.py:84 Test 'test_unexpected_failure' started with params: {}
---------------------------- Captured log teardown -----------------------------
INFO     pytest_report_plugin.plugin:plugin.py:91 04bba2ee-a4f7-4790-b95b-5902c999883c FAILED
INFO     pytest_report_plugin.plugin:plugin.py:299 Finished test: 04bba2ee-a4f7-4790-b95b-5902c999883c, Status: FAILED, Exception: /home/rosh/projects/report-plugin/pytest_report_plugin/tests/test_all_outcomes.py:20: assert False, Duration: 0.000250323999352986
____________________________ test_examples[nan-42] _____________________________

left = nan, right = 42

    @pytest.mark.parametrize(
        "left, right",
        (
            (2, 2),
            pytest.param(3.14, 5.55, marks=pytest.mark.skip("Skipped!")),
            (float("nan"), 42),
        ),
    )
    def test_examples(left, right):
>       assert left + right == right + left
E       assert (nan + 42) == (42 + nan)

tests/test_plugin.py:14: AssertionError
------------------------------ Captured log setup ------------------------------
INFO     pytest_report_plugin.plugin:plugin.py:263 Started test: test_examples[nan-42]
INFO     pytest_report_plugin.plugin:plugin.py:84 Test 'test_examples[nan-42]' started with params: {'left': nan, 'right': 42}
---------------------------- Captured log teardown -----------------------------
INFO     pytest_report_plugin.plugin:plugin.py:91 9249d4ee-3eb4-4161-af8c-8f17fd2aa7c3 FAILED
INFO     pytest_report_plugin.plugin:plugin.py:299 Finished test: 9249d4ee-3eb4-4161-af8c-8f17fd2aa7c3, Status: FAILED, Exception: /home/rosh/projects/report-plugin/pytest_report_plugin/tests/test_plugin.py:14: assert (nan + 42) == (42 + nan), Duration: 0.00045002399929217063
_______________________________ test_properties ________________________________

    @given(left=NUMBER, right=NUMBER)
>   def test_properties(left, right):

tests/test_plugin.py:20: 
_ _ _ _ _ _ _ _ _ _ _ _ _ _ _ _ _ _ _ _ _ _ _ _ _ _ _ _ _ _ _ _ _ _ _ _ _ _ _ _ 

left = 0, right = nan

    @given(left=NUMBER, right=NUMBER)
    def test_properties(left, right):
>       assert left + right == right + left
E       assert (0 + nan) == (nan + 0)
E       Falsifying example: test_properties(
E           left=0,
E           right=nan,  # Saw 1 signaling NaN
E       )
E       Explanation:
E           These lines were always and only run by failing examples:
E               /home/rosh/.local/lib/python3.8/site-packages/_pytest/assertion/util.py:265

tests/test_plugin.py:21: AssertionError
------------------------------ Captured log setup ------------------------------
INFO     pytest_report_plugin.plugin:plugin.py:263 Started test: test_properties
INFO     pytest_report_plugin.plugin:plugin.py:84 Test 'test_properties' started with params: {}
---------------------------- Captured log teardown -----------------------------
INFO     pytest_report_plugin.plugin:plugin.py:91 d0e61e2a-6d54-4795-9704-4e9c59830c90 FAILED
INFO     pytest_report_plugin.plugin:plugin.py:299 Finished test: d0e61e2a-6d54-4795-9704-4e9c59830c90, Status: FAILED, Exception: /home/rosh/projects/report-plugin/pytest_report_plugin/tests/test_plugin.py:21: assert (0 + nan) == (nan + 0), Duration: 0.43633109500115097
=========================== short test summary info ============================
FAILED tests/test_all_outcomes.py::test_unexpected_failure - assert False
FAILED tests/test_plugin.py::test_examples[nan-42] - assert (nan + 42) == (42...
FAILED tests/test_plugin.py::test_properties - assert (0 + nan) == (nan + 0)
============== 3 failed, 3 passed, 2 skipped, 1 xfailed in 0.90s ===============
